Workbook

Sheet Евгений Ж.
D1: Продажи | AT1: Сопровождение клиентов | CR1: Рассчеты | EA1: Эффективность | ET1: Заработная плата | FN1: Нарушения регламента работы
A2: Ноябрь 2022 | D2: Показатели | M2: Дата | N2: 44866 | O2: 44867 | P2: 44868 | Q2: 44869 | R2: 44870 | S2: 44871 | T2: 44872 | U2: 44873 | V2: 44874 | W2: 44875 | X2: 44876 | Y2: 44877 | Z2: 44878 | AA2: 44879 | AB2: 44880 | AC2: 44881 | AD2: 44882 | AE2: 44883 | AF2: 44884 | AG2: 44885 | AH2: 44886 | AI2: 44887 | AJ2: 44888 | AK2: 44889 | AL2: 44890 | AM2: 44891 | AN2: 44892 | AO2: 44893 | AP2: 44894 | AQ2: 44895 | AT2: Название проекта | CR2: Премия | CU2: Ключевые показатели | DH2: Факт | DK2: План | DN2: Бонус | DQ2: Вып 100% | DT2: Вып в % | DW2: Днев ПЛ | EA2: Ключевые конверсии | EO2: Факт | EQ2: Сред | ET2: Мотивация менеджера | FJ2: Сумма | FN2: Дисциплинарные нарушения | FZ2: Сумм | GB2: 44531 | GC2: 44532 | GD2: 44533 | GE2: 44534 | GF2: 44535 | GG2: 44536 | GH2: 44537 | GI2: 44538 | GJ2: 44539 | GK2: 44540 | GL2: 44541 | GM2: 44542 | GN2: 44543 | GO2: 44544 | GP2: 44545 | GQ2: 44546 | GR2: 44547 | GS2: 44548 | GT2: 44549 | GU2: 44550 | GV2: 44551 | GW2: 44552 | GX2: 44553 | GY2: 44554 | GZ2: 44555 | HA2: 44556 | HB2: 44557 | HC2: 44558 | HD2: 44559 | HE2: 44560 | HF2: 44561 | HG2: Итого
CR3: 0 | CU3: Количество новых лидов | DH3: =SUM(N6:AR6) -> 59 | DK3: 10 | DN3: 0 | DQ3: 0 | DT3: 0 | DW3: =(DK3-DH3)/'График'!AK4 -> -2.1304348 | EA3: Из лида в одобренный тест | EO3: =DH5*100/DH3 -> 33.898305 | ET3: Сумма штрафов | FJ3: =HG12 -> 0
AT4: Сумма | CR4: 0 | CU4: Количество результативных звонков | DH4: =SUM(N7:AR7) -> 197 | DK4: 10 | DN4: =2500*DT4/100 -> 2500 | DQ4: =IF(DH4<DK4,DH4,IF(DH4>=DK4,DK4)) -> 10 | DT4: =DQ4*100/DK4 -> 100 | DW4: =(DK4-DH4)/'График'!AK4 -> -8.1304348 | EA4: Из лида в оплаченный тест | EO4: =DH6*100/DH3 -> 15.254237 | ET4: Бонус за выполнение KPI | FJ4: =sum(DN4:DP7,DN9) -> 7500
AT5: Количество | AX5: 1 | BA5: 1 | BD5: 3 | BG5: 4 | BJ5: 5 | BM5: 6 | BP5: 7 | BS5: 8 | BV5: 9 | BY5: 10 | CB5: 11 | CE5: 12 | CH5: 13 | CK5: 14 | CN5: 15 | CR5: 0 | CU5: Кол-во одобренных тестов | DH5: =SUM(N8:AR8) -> 20 | DK5: 10 | DN5: =2500*DT5/100 -> 2500 | DQ5: =IF(DH5<DK5,DH5,IF(DH5>=DK5,DK5)) -> 10 | DT5: =DQ5*100/DK5 -> 100 | DW5: =(DK5-DH5)/'График'!AK4 -> -0.43478261 | EA5: Из лида в заключенный договор | EO5: =DH7*100/DH3 -> 0 | ET5: Общий % выполнения KPI | FJ5: =sum(DT4,DT5,DT6,DT7,DT9)/5 -> 60
D6: Кол-во новых лидов | V6: 2 | W6: 7 | X6: 4 | Y6: 0 | AA6: 10 | AB6: 0 | AC6: 0 | AD6: 4 | AE6: 5 | AF6: 0 | AH6: 1 | AI6: 12 | AJ6: 0 | AK6: 0 | AL6: 0 | AM6: 8 | AO6: 2 | AP6: 2 | AQ6: 2 | AT6: 2 месяц | AW6: % | AX6: 10 | BA6: 10 | BD6: 10 | BG6: 10 | BJ6: 10 | BM6: 10 | BP6: 10 | BS6: 10 | BV6: 10 | BY6: 10 | CB6: 10 | CE6: 10 | CH6: 10 | CK6: 10 | CN6: 10 | CR6: 10000 | CU6: Кол-во оплаченных тестов | DH6: =SUM(N9:AR9) -> 9 | DK6: 7 | DN6: =2500*DT6/100 -> 2500 | DQ6: =IF(DH6<DK6,DH6,IF(DH6>=DK6,DK6)) -> 7 | DT6: =DQ6*100/DK6 -> 100 | DW6: =(DK6-DH6)/'График'!AK4 -> -0.086956522 | EA6: Из результативного звонка в одобренный тест | EO6: =DH5*100/DH4 -> 10.152284 | ET6: Премия за платные тесты | FJ6: =sum(AX14:CP14) -> 14000 | FN6: Ведение CRM | FZ6: 200 | HG6: =sum(GB6:HF6)*FZ6 -> 0
D7: Кол-во результативных звонков | V7: 12 | W7: 11 | X7: 9 | Y7: 2 | AA7: 17 | AB7: 9 | AC7: 8 | AD7: 13 | AE7: 14 | AF7: 1 | AH7: 11 | AI7: 15 | AJ7: 5 | AK7: 7 | AL7: 8 | AM7: 13 | AO7: 18 | AP7: 14 | AQ7: 10 | AT7: =SUM(AX7:CO7) -> 0 | AX7: =(AX4*AX6)/100 -> 0 | BA7: =(BA4*BA6)/100 -> 0 | BD7: =(BD4*BD6)/100 -> 0 | BG7: =(BG4*BG6)/100 -> 0 | BJ7: =(BJ4*BJ6)/100 -> 0 | BM7: =(BM4*BM6)/100 -> 0 | BP7: =(BP4*BP6)/100 -> 0 | BS7: =(BS4*BS6)/100 -> 0 | BV7: =(BV4*BV6)/100 -> 0 | BY7: =(BY4*BY6)/100 -> 0 | CB7: =(CB4*CB6)/100 -> 0 | CE7: =(CE4*CE6)/100 -> 0 | CH7: =(CH4*CH6)/100 -> 0 | CK7: =(CK4*CK6)/100 -> 0 | CN7: =(CN4*CN6)/100 -> 0 | CR7: 2500 | CU7: Кол-во заключенных договоров | DH7: =SUM(N10:AR10) -> 0 | DK7: 1 | DN7: =2500*DT7/100 -> 0 | DQ7: =IF(DH7<DK7,DH7,IF(DH7>=DK7,DK7)) -> 0 | DT7: =DQ7*100/DK7 -> 0 | DW7: =(DK7-DH7)/'График'!AK4 -> 0.043478261 | EA7: Из звонка в проведенный тест | EO7: =DH6*100/DH4 -> 4.5685279 | ET7: Премия за сопровождение проектов за второй месяц | FN7: Соблюдение регламентов и скриптов | FZ7: 200 | HG7: =sum(GB7:HF7)*FZ7 -> 0
D8: Кол-во одобренных тестов | V8: 3 | W8: 1 | X8: 1 | Y8: 0 | AA8: 3 | AB8: 1 | AC8: 0 | AD8: 2 | AE8: 1 | AF8: 0 | AH8: 0 | AI8: 2 | AJ8: 0 | AK8: 1 | AL8: 0 | AM8: 2 | AO8: 1 | AP8: 1 | AQ8: 1 | AT8: 3 месяц | AW8: % | AX8: 5 | BA8: 5 | BD8: 5 | BG8: 10 | BJ8: 10 | BM8: 10 | BP8: 10 | BS8: 10 | BV8: 10 | BY8: 10 | CB8: 10 | CE8: 10 | CH8: 10 | CK8: 10 | CN8: 10 | CR8: 0 | CU8: Кол-во позиций в договоре | DH8: =SUM(N11:AR11) -> 0 | DK8: 2 | DN8: 0 | DQ8: 0 | DT8: 0 | DW8: =(DK8-DH8)/'График'!AK4 -> 0.086956522 | EA8: Из звонка в заключенный договор | EO8: =DH7*100/DH4 -> 0 | ET8: Премия за сопровождение проектов за третий месяц | FN8: Вовремя/неверно сданная отчетность | FZ8: 500 | HG8: =sum(GB8:HF8)*FZ8 -> 0
D9: Кол-во оплаченных тестов | V9: 2 | W9: 1 | X9: 0 | Y9: 0 | AA9: 1 | AB9: 0 | AC9: 0 | AD9: 0 | AE9: 1 | AF9: 0 | AH9: 1 | AI9: 0 | AJ9: 0 | AK9: 1 | AL9: 0 | AM9: 0 | AO9: 1 | AP9: 0 | AQ9: 1 | AT9: =SUM(AX9:CO9) -> 0 | AX9: =(AX4*AX8)/100 -> 0 | BA9: =(BA4*BA8)/100 -> 0 | BD9: =(BD4*BD8)/100 -> 0 | BG9: =(BG4*BG8)/100 -> 0 | BJ9: =(BJ4*BJ8)/100 -> 0 | BM9: =(BM4*BM8)/100 -> 0 | BP9: =(BP4*BP8)/100 -> 0 | BS9: =(BS4*BS8)/100 -> 0 | BV9: =(BV4*BV8)/100 -> 0 | BY9: =(BY4*BY8)/100 -> 0 | CB9: =(CB4*CB8)/100 -> 0 | CE9: =(CE4*CE8)/100 -> 0 | CH9: =(CH4*CH8)/100 -> 0 | CK9: =(CK4*CK8)/100 -> 0 | CN9: =(CN4*CN8)/100 -> 0 | CR9: 2500 | CU9: Сумма продаж | DH9: =SUM(N12:AR12) -> 0 | DK9: 20000 | DN9: =5000*DT9/100 -> 0 | DQ9: =IF(DH9<DK9,DH9,IF(DH9>=DK9,DK9)) -> 0 | DT9: =DQ9*100/DK9 -> 0 | DW9: =(DK9-DH9)/'График'!AK4 -> 869.56522 | EA9: Из одобренного теста в проведенный тест | EO9: =DH6*100/DH5 -> 45 | ET9: Зарплата менеджера без учета командного плана | FJ9: =if(FJ5>84,DH9*15%+FJ4,if(FJ5<85,DH9*10%+FJ4)) -> 7500 | FN9: Опоздание без ув. причины | FZ9: 800 | HG9: =sum(GB9:HF9)*FZ9 -> 0
D10: Кол-во заключенных договоров | V10: 0 | W10: 0 | X10: 0 | Y10: 0 | AA10: 0 | AB10: 0 | AC10: 0 | AD10: 0 | AE10: 0 | AF10: 0 | AH10: 0 | AI10: 0 | AJ10: 0 | AK10: 0 | AL10: 0 | AM10: 0 | AO10: 0 | AP10: 0 | AQ10: 0 | AT10: Платные тесты | CR10: 10000 | CU10: Командный план | DH10: =sum(DH9+'Александр'!BF11) -> 0 | DK10: 80000 | DN10: 10000 | DT10: =DH10*100/DK10 -> 0 | DW10: =(DK10-DH10)/'График'!AK4 -> 3478.2609 | EA10: Из одобренного теста в заключенный договор | EO10: =DH7*100/DH5 -> 0 | ET10: Зарплата менеджера с учетом командного плана | FJ10: =if(DH10>=DK10,FJ9+DN10,if(DH10<DK10,FJ9))-HG12 -> 7500 | FN10: Неявка на работу | FZ10: 1500 | HG10: =sum(GB10:HF10)*FZ10 -> 0
D11: Кол-во позиций в договоре | V11: 0 | W11: 0 | X11: 0 | Y11: 0 | AA11: 0 | AB11: 0 | AC11: 0 | AD11: 0 | AE11: 0 | AF11: 0 | AH11: 0 | AI11: 0 | AJ11: 0 | AK11: 0 | AL11: 0 | AM11: 0 | AO11: 0 | AP11: 0 | AQ11: 0 | AT11: Название проекта | AX11: Уфа ИП Хатмуллин | BA11: Казань МебБюро | BD11: РостовНД Кухни61 | BG11: СПБ Штонда | BJ11: Саратов Perfektum | BM11: Волгоград Коновалов | BP11: Краснодар ТаймМебель | BS11: Тула КитченКа2 | BV11: Название Проекта | BY11: Название Проекта | CB11: Название Проекта | CE11: Название Проекта | CH11: Название Проекта | CK11: Название Проекта | CN11: Название Проекта | CR11: 0 | CU11: Остаток до выполнения личного плана | DH11: =DK9-DH9 -> 20000 | EA11: Из теста в заключенный договор | EO11: =DH7*100/DH6 -> 0 | FH11: Итого | FJ11: =sum(FJ10+FJ7+FJ8+FJ6) -> 21500 | FN11: Неверно составленное ТЗ | FZ11: 1000 | HG11: =sum(GB11:HF11)*FZ11 -> 0
D12: Сумма продаж | V12: 0 | W12: 0 | X12: 0 | Y12: 0 | AA12: 0 | AB12: 0 | AC12: 0 | AD12: 0 | AE12: 0 | AF12: 0 | AH12: 0 | AI12: 0 | AJ12: 0 | AK12: 0 | AL12: 0 | AM12: 0 | AO12: 0 | AP12: 0 | AQ12: 0 | CR12: 0 | CU12: Средний чек | DH12: =DH9/DH7 -> #DIV/0! | HE12: Итого | HG12: =sum(HG6:HG11) -> 0
AT13: Сумма | AX13: 5000 | BA13: 10000 | BD13: 10000 | BG13: 10000 | BJ13: 10000 | BM13: 5000 | BP13: 10000 | BS13: 10000 | CR13: 0 | CU13: Общее количество звонков
AT14: 20 | AW14: % | AX14: =AX13*AT14/100 -> 1000 | BA14: =BA13*AT14/100 -> 2000 | BD14: =BD13*AT14/100 -> 2000 | BG14: =BG13*AT14/100 -> 2000 | BJ14: =BJ13*AT14/100 -> 2000 | BM14: =BM13*AT14/100 -> 1000 | BP14: =BP13*AT14/100 -> 2000 | BS14: =BS13*AT14/100 -> 2000 | BV14: =BV13*AT14/100 -> 0 | BY14: =BY13*AT14/100 -> 0 | CB14: =CB13*AT14/100 -> 0 | CE14: =CE13*AT14/100 -> 0 | CH14: =CH13*AT14/100 -> 0 | CK14: =CK13*AT14/100 -> 0 | CN14: =CN13*AT14/100 -> 0 | CR14: 0 | CU14: Общее количество минут разговора
CR15: 15000 | CU15: Среднее количество изделий в договоре | DH15: =(DH7/DH8) -> #DIV/0!
D19: Продажи | AT19: Сопровождение клиентов | CR19: Рассчеты | EA19: Эффективность | ET19: Заработная плата | FN19: Нарушения регламента работы
A20: Декабрь 2022 | D20: Показатели | M20: Дата | N20: 44896 | O20: 44897 | P20: 44898 | Q20: 44899 | R20: 44900 | S20: 44901 | T20: 44902 | U20: 44903 | V20: 44904 | W20: 44905 | X20: 44906 | Y20: 44907 | Z20: 44908 | AA20: 44909 | AB20: 44910 | AC20: 44911 | AD20: 44912 | AE20: 44913 | AF20: 44914 | AG20: 44915 | AH20: 44916 | AI20: 44917 | AJ20: 44918 | AK20: 44919 | AL20: 44920 | AM20: 44921 | AN20: 44922 | AO20: 44923 | AP20: 44924 | AQ20: 44925 | AR20: 44926 | AT20: Название проекта | AX20: РостовНД Кухни61 | CR20: Премия | CU20: Ключевые показатели | DH20: Факт | DK20: План | DN20: Бонус | DQ20: Вып 100% | DT20: Вып в % | DW20: Днев ПЛ | EA20: Ключевые конверсии | EO20: Факт | EQ20: Сред | ET20: Мотивация менеджера | FJ20: Сумма | FN20: Дисциплинарные нарушения | FZ20: Сумм | GB20: 44317 | GC20: 44318 | GD20: 44319 | GE20: 44320 | GF20: 44321 | GG20: 44322 | GH20: 44323 | GI20: 44324 | GJ20: 44325 | GK20: 44326 | GL20: 44327 | GM20: 44328 | GN20: 44329 | GO20: 44330 | GP20: 44331 | GQ20: 44332 | GR20: 44333 | GS20: 44334 | GT20: 44335 | GU20: 44336 | GV20: 44337 | GW20: 44338 | GX20: 44339 | GY20: 44340 | GZ20: 44341 | HA20: 44342 | HB20: 44343 | HC20: 44344 | HD20: 44345 | HE20: 44346 | HF20: 44347 | HG20: Итого
CR21: 0 | CU21: Количество новых лидов | DH21: =SUM(N24:AR24) -> 32 | DK21: 50 | DN21: 0 | DQ21: 0 | DT21: 0 | DW21: =(DK21-DH21)/'График'!AK8 -> 0.7826087 | EA21: Из лида в одобренный тест | EO21: =DH23*100/DH21 -> 15.625 | EQ21: =((DH23*100/DH21)+EO3)/2 -> 24.761653 | ET21: Сумма штрафов | FJ21: =HG30 -> 0
AT22: Сумма | AX22: 20000 | CR22: 0 | CU22: Количество результативных звонков | DH22: =SUM(N25:AR25) -> 241 | DK22: 190 | DN22: =2500*DT22/100 -> 2500 | DQ22: =IF(DH22<DK22,DH22,IF(DH22>=DK22,DK22)) -> 190 | DT22: =DQ22*100/DK22 -> 100 | DW22: =(DK22-DH22)/'График'!AK8 -> -2.2173913 | EA22: Из лида в оплаченный тест | EO22: =DH24*100/DH21 -> 15.625 | EQ22: =((DH23*100/DH21)+EO4)/2 -> 15.439619 | ET22: Бонус за выполнение KPI | FJ22: =sum(DN22:DP25,DN27) -> 11410.714
AT23: Количество | AX23: 1 | BA23: 2 | BD23: 3 | BG23: 4 | BJ23: 5 | BM23: 6 | BP23: 7 | BS23: 8 | BV23: 9 | BY23: 10 | CB23: 11 | CE23: 12 | CH23: 13 | CK23: 14 | CN23: 15 | CR23: 0 | CU23: Кол-во одобренных тестов | DH23: =SUM(N26:AR26) -> 5 | DK23: 20 | DN23: =2500*DT23/100 -> 625 | DQ23: =IF(DH23<DK23,DH23,IF(DH23>=DK23,DK23)) -> 5 | DT23: =DQ23*100/DK23 -> 25 | DW23: =(DK23-DH23)/'График'!AK8 -> 0.65217391 | EA23: Из лида в заключенный договор | EO23: =DH25*100/DH21 -> 6.25 | EQ23: =((DH25*100/DH21)+EO5)/2 -> 3.125 | ET23: Общий % выполнения KPI | FJ23: =sum(DT22,DT23,DT24,DT25,DT27)/5 -> 75.285714
D24: Кол-во новых лидов | N24: 0 | O24: 0 | P24: 0 | R24: 8 | S24: 1 | T24: 4 | U24: 1 | V24: 1 | W24: 0 | X24: 5 | Y24: 5 | Z24: 6 | AA24: 0 | AB24: 1 | AG24: 0 | AH24: 0 | AI24: 0 | AJ24: 0 | AK24: 0 | AM24: 0 | AN24: 0 | AO24: 0 | AP24: 0 | AQ24: 0 | AT24: 2 месяц | AW24: % | BD24: 10 | BG24: 10 | BJ24: 10 | BM24: 10 | BP24: 10 | BS24: 10 | BV24: 10 | BY24: 10 | CB24: 10 | CE24: 10 | CH24: 10 | CK24: 10 | CN24: 10 | CR24: 10000 | CU24: Кол-во оплаченных тестов | DH24: =SUM(N27:AR27) -> 5 | DK24: 7 | DN24: =2500*DT24/100 -> 1785.7143 | DQ24: =IF(DH24<DK24,DH24,IF(DH24>=DK24,DK24)) -> 5 | DT24: =DQ24*100/DK24 -> 71.428571 | DW24: =(DK24-DH24)/'График'!AK8 -> 0.086956522 | EA24: Из результативного звонка в одобренный тест | EO24: =DH23*100/DH22 -> 2.0746888 | EQ24: =((DH23*100/DH22)+EO6)/2 -> 6.1134865 | ET24: Премия за платные тесты | FJ24: =sum(AX32:CP32) -> 7000 | FN24: Ведение CRM | FZ24: 200 | HG24: =sum(GB24:HF24)*FZ24 -> 0
D25: Кол-во результативных звонков | N25: 16 | O25: 12 | P25: 5 | R25: 11 | S25: 11 | T25: 13 | U25: 16 | V25: 16 | W25: 15 | X25: 17 | Y25: 17 | Z25: 9 | AA25: 7 | AB25: 9 | AG25: 18 | AH25: 8 | AI25: 8 | AJ25: 6 | AK25: 3 | AM25: 3 | AN25: 3 | AO25: 3 | AP25: 13 | AQ25: 2 | AT25: =SUM(AX25:CO25) -> 0 | AX25: =(AX22*AX24)/100 -> 0 | BA25: =(BA22*BA24)/100 -> 0 | BD25: =(BD22*BD24)/100 -> 0 | BG25: =(BG22*BG24)/100 -> 0 | BJ25: =(BJ22*BJ24)/100 -> 0 | BM25: =(BM22*BM24)/100 -> 0 | BP25: =(BP22*BP24)/100 -> 0 | BS25: =(BS22*BS24)/100 -> 0 | BV25: =(BV22*BV24)/100 -> 0 | BY25: =(BY22*BY24)/100 -> 0 | CB25: =(CB22*CB24)/100 -> 0 | CE25: =(CE22*CE24)/100 -> 0 | CH25: =(CH22*CH24)/100 -> 0 | CK25: =(CK22*CK24)/100 -> 0 | CN25: =(CN22*CN24)/100 -> 0 | CR25: 2500 | CU25: Кол-во заключенных договоров | DH25: =SUM(N28:AR28) -> 2 | DK25: 2 | DN25: =2500*DT25/100 -> 2500 | DQ25: =IF(DH25<DK25,DH25,IF(DH25>=DK25,DK25)) -> 2 | DT25: =DQ25*100/DK25 -> 100 | DW25: =(DK25-DH25)/'График'!AK8 -> 0 | EA25: Из звонка в проведенный тест | EO25: =DH24*100/DH22 -> 2.0746888 | EQ25: =((DH24*100/DH22)+EO7)/2 -> 3.3216084 | ET25: Премия за сопровождение проектов за второй месяц | FJ25: =AT7 -> 0 | FN25: Соблюдение регламентов и скриптов | FZ25: 200 | HG25: =sum(GB25:HF25)*FZ25 -> 0
D26: Кол-во одобренных тестов | N26: 0 | O26: 0 | P26: 1 | R26: 0 | S26: 0 | T26: 1 | U26: 0 | V26: 0 | W26: 0 | X26: 0 | Y26: 0 | Z26: 0 | AA26: 0 | AB26: 0 | AG26: 0 | AH26: 0 | AI26: 0 | AJ26: 0 | AK26: 1 | AM26: 0 | AN26: 0 | AO26: 0 | AP26: 2 | AQ26: 0 | AT26: 3 месяц | AW26: % | BA26: 5 | BD26: 5 | BG26: 5 | BJ26: 5 | BM26: 5 | BP26: 5 | BS26: 5 | BV26: 5 | BY26: 5 | CB26: 5 | CE26: 5 | CH26: 5 | CK26: 5 | CN26: 5 | CR26: 0 | CU26: Кол-во позиций в договоре | DH26: =SUM(N29:AR29) -> 2 | DK26: 1 | DN26: 0 | DQ26: 0 | DT26: 0 | DW26: =(DK26-DH26)/'График'!AK8 -> -0.043478261 | EA26: Из звонка в заключенный договор | EO26: =DH25*100/DH22 -> 0.82987552 | EQ26: =((DH25*100/DH22)+EO8)/2 -> 0.41493776 | ET26: Премия за сопровождение проектов за третий месяц | FN26: Вовремя/неверно сданная отчетность | FZ26: 500 | HG26: =sum(GB26:HF26)*FZ26 -> 0
D27: Кол-во оплаченных тестов | N27: 0 | O27: 0 | P27: 0 | R27: 0 | S27: 1 | T27: 0 | U27: 0 | V27: 0 | W27: 0 | X27: 1 | Y27: 1 | Z27: 0 | AA27: 0 | AB27: 0 | AG27: 0 | AH27: 0 | AI27: 0 | AJ27: 0 | AK27: 0 | AM27: 0 | AN27: 0 | AO27: 0 | AP27: 2 | AQ27: 0 | AT27: =SUM(AX27:CO27) -> 0 | AX27: =(AX22*AX26)/100 -> 0 | BA27: =(BA22*BA26)/100 -> 0 | BD27: =(BD22*BD26)/100 -> 0 | BG27: =(BG22*BG26)/100 -> 0 | BJ27: =(BJ22*BJ26)/100 -> 0 | BM27: =(BM22*BM26)/100 -> 0 | BP27: =(BP22*BP26)/100 -> 0 | BS27: =(BS22*BS26)/100 -> 0 | BV27: =(BV22*BV26)/100 -> 0 | BY27: =(BY22*BY26)/100 -> 0 | CB27: =(CB22*CB26)/100 -> 0 | CE27: =(CE22*CE26)/100 -> 0 | CH27: =(CH22*CH26)/100 -> 0 | CK27: =(CK22*CK26)/100 -> 0 | CN27: =(CN22*CN26)/100 -> 0 | CR27: 2500 | CU27: Сумма продаж | DH27: =SUM(O30:AR30) -> 40000 | DK27: 50000 | DN27: =5000*DT27/100 -> 4000 | DQ27: =IF(DH27<DK27,DH27,IF(DH27>=DK27,DK27)) -> 40000 | DT27: =DQ27*100/DK27 -> 80 | DW27: =(DK27-DH27)/'График'!AK8 -> 434.78261 | EA27: Из одобренного теста в проведенный тест | EO27: =DH24*100/DH23 -> 100 | EQ27: =((DH24*100/DH23)+EO9)/2 -> 72.5 | ET27: Зарплата менеджера без учета командного плана | FJ27: =if(FJ23>84,DH27*15%+FJ22,if(FJ23<85,DH27*5%+FJ22)) -> 13410.714 | FN27: Опоздание без ув. причины | FZ27: 800 | HG27: =sum(GB27:HF27)*FZ27 -> 0
D28: Кол-во заключенных договоров | N28: 0 | O28: 0 | P28: 0 | R28: 1 | S28: 0 | T28: 0 | U28: 1 | V28: 0 | W28: 0 | X28: 0 | Y28: 0 | Z28: 0 | AA28: 0 | AB28: 0 | AG28: 0 | AH28: 0 | AI28: 0 | AJ28: 0 | AK28: 0 | AM28: 0 | AN28: 0 | AO28: 0 | AP28: 0 | AQ28: 0 | AT28: Платные тесты | CR28: 10000 | CU28: Командный план | DH28: =sum(DH27+'Александр'!BI28) -> 40000 | DK28: 80000 | DN28: 10000 | DT28: =DH28*100/DK28 -> 50 | DW28: =(DK28-DH28)/'График'!AK8 -> 1739.1304 | EA28: Из одобренного теста в заключенный договор | EO28: =DH25*100/DH23 -> 40 | EQ28: =((DH25*100/DH23)+EO10)/2 -> 20 | ET28: Зарплата менеджера с учетом командного плана | FJ28: =if(DH28>=DK28,FJ27+DN28,if(DH28<DK28,FJ27))-HG30 -> 13410.714 | FN28: Неявка на работу | FZ28: 1500 | HG28: =sum(GB28:HF28)*FZ28 -> 0
D29: Кол-во позиций в договоре | N29: 0 | O29: 0 | P29: 0 | R29: 1 | S29: 0 | T29: 0 | U29: 1 | V29: 0 | W29: 0 | X29: 0 | Y29: 0 | Z29: 0 | AA29: 0 | AB29: 0 | AG29: 0 | AH29: 0 | AI29: 0 | AJ29: 0 | AK29: 0 | AM29: 0 | AN29: 0 | AO29: 0 | AP29: 0 | AQ29: 0 | AT29: Название проекта | AX29: Казань ИП Ильясов | BA29: Ижевск МоллиМеб | BD29: Новомосковск ДругаяМебель | BG29: Уфа М-Дизайн | BJ29: Название Проекта | BM29: Название Проекта | BP29: Название Проекта | BS29: Название Проекта | BV29: Название Проекта | BY29: Название Проекта | CB29: Название Проекта | CE29: Название Проекта | CH29: Название Проекта | CK29: Название Проекта | CN29: Название Проекта | CR29: 0 | CU29: Остаток до выполнения личного плана | DH29: =DK27-DH27 -> 10000 | EA29: Из теста в заключенный договор | EO29: =DH25*100/DH24 -> 40 | EQ29: =((DH25*100/DH24)+EO11)/2 -> 20 | FH29: Итого | FJ29: =sum(FJ24+FJ28+FJ25+FJ26) -> 20410.714 | FN29: Неверно составленное ТЗ | FZ29: 1000 | HG29: =sum(GB29:HF29)*FZ29 -> 0
D30: Сумма продаж | N30: 0 | O30: 0 | P30: 0 | R30: 20000 | S30: 0 | T30: 0 | U30: 20000 | V30: 0 | W30: 0 | X30: 0 | Y30: 0 | Z30: 0 | AA30: 0 | AB30: 0 | AG30: 0 | AH30: 0 | AI30: 0 | AJ30: 0 | AK30: 0 | AM30: 0 | AN30: 0 | AO30: 0 | AP30: 0 | AQ30: 0 | CR30: 0 | CU30: Средний чек | DH30: =DH27/DH25 -> 20000 | HE30: Итого | HG30: =sum(HG24:HG29) -> 0
AT31: Сумма | AX31: 10000 | BA31: 10000 | BD31: 10000 | BG31: 5000 | CR31: 0 | CU31: Общее количество звонков
AT32: 20 | AW32: % | AX32: =AX31*AT32/100 -> 2000 | BA32: =BA31*AT32/100 -> 2000 | BD32: =BD31*AT32/100 -> 2000 | BG32: =BG31*AT32/100 -> 1000 | BJ32: =BJ31*AT32/100 -> 0 | BM32: =BM31*AT32/100 -> 0 | BP32: =BP31*AT32/100 -> 0 | BS32: =BS31*AT32/100 -> 0 | BV32: =BV31*AT32/100 -> 0 | BY32: =BY31*AT32/100 -> 0 | CB32: =CB31*AT32/100 -> 0 | CE32: =CE31*AT32/100 -> 0 | CH32: =CH31*AT32/100 -> 0 | CK32: =CK31*AT32/100 -> 0 | CN32: =CN31*AT32/100 -> 0 | CR32: 0 | CU32: Общее количество минут разговора
CR33: 15000 | CU33: Среднее количество позиций в договоре | DH33: =(DH25/DH26) -> 1
D38: Продажи | AT38: Сопровождение клиентов | CR38: Рассчеты KPI | EA38: Эффективность | ET38: Заработная плата* | FN38: Нарушения регламента работы
A39: Январь 2023 | D39: Показатели | M39: Дата | N39: 44562 | O39: 44563 | P39: 44564 | Q39: 44565 | R39: 44566 | S39: 44567 | T39: 44568 | U39: 44569 | V39: 44570 | W39: 44571 | X39: 44572 | Y39: 44573 | Z39: 44574 | AA39: 44575 | AB39: 44576 | AC39: 44577 | AD39: 44578 | AE39: 44579 | AF39: 44580 | AG39: 44581 | AH39: 44582 | AI39: 44583 | AJ39: 44584 | AK39: 44585 | AL39: 44586 | AM39: 44587 | AN39: 44588 | AO39: 44589 | AP39: 44590 | AQ39: 44591 | AR39: 44592 | AT39: Название проекта | AX39: Саратов Перфектум | CR39: Премия | CU39: Ключевые показатели | DH39: Факт | DK39: План | DN39: Бонус ф. | DQ39: Вып. 100% | DT39: Вып в % | DW39: Днев пл. | EA39: Ключевые конверсии | EO39: Факт* | EQ39: Ср* | ET39: Мотивация менеджера | FJ39: Сумма | FN39: Дисциплинарные нарушения | FZ39: Сумм | GB39: 44317 | GC39: 44318 | GD39: 44319 | GE39: 44320 | GF39: 44321 | GG39: 44322 | GH39: 44323 | GI39: 44324 | GJ39: 44325 | GK39: 44326 | GL39: 44327 | GM39: 44328 | GN39: 44329 | GO39: 44330 | GP39: 44331 | GQ39: 44332 | GR39: 44333 | GS39: 44334 | GT39: 44335 | GU39: 44336 | GV39: 44337 | GW39: 44338 | GX39: 44339 | GY39: 44340 | GZ39: 44341 | HA39: 44342 | HB39: 44343 | HC39: 44344 | HD39: 44345 | HE39: 44346 | HF39: 44347 | HG39: Итого
CU40: Количество новых лидов | DH40: =SUM(N43:AR43) -> 27 | DK40: 0 | DN40: =CR40*DT40/100 -> 0 | DQ40: 0 | DT40: 0 | DW40: =(DK40-DH40)/'График'!AK12 -> -1.173913 | EA40: Из лида в одобренный тест | EO40: =DH42*100/DH40 -> 22.222222 | EQ40: =((DH42*100/DH40)+EO21)/2 -> 18.923611 | ET40: Сумма штрафов | FJ40: =HG49 -> 0
AT41: Сумма | AX41: 25000 | CU41: Количество результативных звонков | DH41: =SUM(N44:AR44) -> 150 | DK41: 80 | DN41: =CR41*DT41/100 -> 0 | DQ41: =IF(DH41<DK41,DH41,IF(DH41>=DK41,DK41)) -> 80 | DT41: =DQ41*100/DK41 -> 100 | DW41: =(DK41-DH41)/'График'!AK12 -> -3.0434783 | EA41: Из лида в оплаченный тест | EO41: =DH43*100/DH40 -> 18.518519 | EQ41: =((DH42*100/DH40)+EO22)/2 -> 18.923611 | ET41: Бонус за выполнение KPI | FJ41: =sum(DN43,DN44,DN46) -> 10000
AT42: Количество | AX42: 1 | BA42: 1 | CU42: Кол-во одобренных тестов | DH42: =SUM(N45:AR45) -> 6 | DK42: 5 | DN42: =CR42*DT42/100 -> 0 | DQ42: =IF(DH42<DK42,DH42,IF(DH42>=DK42,DK42)) -> 5 | DT42: =DQ42*100/DK42 -> 100 | DW42: =(DK42-DH42)/'График'!AK12 -> -0.043478261 | EA42: Из лида в заключенный договор | EO42: =DH44*100/DH40 -> 0 | EQ42: =((DH44*100/DH40)+EO23)/2 -> 3.125 | ET42: Общий % выполнения KPI | FJ42: =sum(DT43,DT44,DT46)/3 -> 33.333333
D43: Кол-во новых лидов | O43: 0 | T43: 0 | U43: 0 | V43: 0 | W43: 0 | X43: 1 | Y43: 0 | Z43: 0 | AA43: 0 | AB43: 0 | AC43: 5 | AE43: 4 | AF43: 0 | AK43: 7 | AL43: 3 | AM43: 2 | AN43: 4 | AQ43: 1 | AT43: 2 месяц | AW43: % | AX43: 10 | BA43: 5 | BD43: 10 | BG43: 10 | BJ43: 10 | BM43: 10 | BP43: 10 | BS43: 10 | BV43: 10 | BY43: 10 | CB43: 10 | CE43: 10 | CH43: 10 | CK43: 10 | CN43: 10 | CR43: 10000 | CU43: Кол-во оплаченных тестов | DH43: =SUM(N46:AR46) -> 5 | DK43: 5 | DN43: =CR43*DT43/100 -> 10000 | DQ43: =IF(DH43<DK43,DH43,IF(DH43>=DK43,DK43)) -> 5 | DT43: =DQ43*100/DK43 -> 100 | DW43: =(DK43-DH43)/'График'!AK12 -> 0 | EA43: Из результативного звонка в одобренный тест | EO43: =DH42*100/DH41 -> 4 | EQ43: =((DH42*100/DH41)+EO24)/2 -> 3.0373444 | ET43: Премия за платные тесты | FJ43: =sum(AX52:CP52) -> 6000 | FN43: Ведение CRM | FZ43: 200 | HG43: =sum(GB43:HF43)*FZ43 -> 0
D44: Кол-во результативных звонков | O44: 1 | T44: 14 | U44: 2 | V44: 22 | W44: 2 | X44: 8 | Y44: 17 | Z44: 9 | AA44: 3 | AB44: 3 | AC44: 7 | AE44: 12 | AF44: 0 | AK44: 6 | AL44: 2 | AM44: 20 | AN44: 6 | AQ44: 16 | AT44: =SUM(AX44:CO44) -> 2500 | AX44: =(AX41*AX43)/100 -> 2500 | BA44: =(BA41*BA43)/100 -> 0 | BD44: =(BD41*BD43)/100 -> 0 | BG44: =(BG41*BG43)/100 -> 0 | BJ44: =(BJ41*BJ43)/100 -> 0 | BM44: =(BM41*BM43)/100 -> 0 | BP44: =(BP41*BP43)/100 -> 0 | BS44: =(BS41*BS43)/100 -> 0 | BV44: =(BV41*BV43)/100 -> 0 | BY44: =(BY41*BY43)/100 -> 0 | CB44: =(CB41*CB43)/100 -> 0 | CE44: =(CE41*CE43)/100 -> 0 | CH44: =(CH41*CH43)/100 -> 0 | CK44: =(CK41*CK43)/100 -> 0 | CN44: =(CN41*CN43)/100 -> 0 | CR44: 2500 | CU44: Кол-во заключенных договоров | DH44: =SUM(N47:AR47) -> 0 | DK44: 1 | DN44: =CR44*DT44/100 -> 0 | DQ44: =IF(DH44<DK44,DH44,IF(DH44>=DK44,DK44)) -> 0 | DT44: =DQ44*100/DK44 -> 0 | DW44: =(DK44-DH44)/'График'!AK12 -> 0.043478261 | EA44: Из звонка в проведенный тест | EO44: =DH43*100/DH41 -> 3.3333333 | EQ44: =((DH43*100/DH41)+EO25)/2 -> 2.7040111 | ET44: Премия за сопровождение проектов за второй месяц | FJ44: =AT44 -> 2500 | FN44: Соблюдение регламентов и скриптов | FZ44: 200 | HG44: =sum(GB44:HF44)*FZ44 -> 0
D45: Кол-во одобренных тестов | O45: 0 | T45: 0 | U45: 0 | V45: 0 | W45: 0 | X45: 1 | Y45: 0 | Z45: 1 | AA45: 1 | AB45: 1 | AC45: 0 | AE45: 1 | AF45: 0 | AK45: 0 | AL45: 0 | AM45: 0 | AN45: 1 | AQ45: 0 | AT45: 3 месяц | AW45: % | BA45: 5 | BD45: 5 | BG45: 5 | BJ45: 5 | BM45: 5 | BP45: 5 | BS45: 5 | BV45: 5 | BY45: 5 | CB45: 5 | CE45: 5 | CH45: 5 | CK45: 5 | CN45: 5 | CU45: Кол-во позиций в договоре | DH45: =SUM(N48:AR48) -> 0 | DK45: 0 | DN45: =CR45*DT45/100 -> 0 | DQ45: 0 | DT45: 0 | DW45: =(DK45-DH45)/'График'!AK12 -> 0 | EA45: Из звонка в заключенный договор | EO45: =DH44*100/DH41 -> 0 | EQ45: =((DH44*100/DH41)+EO26)/2 -> 0.41493776 | ET45: Премия за сопровождение проектов за третий месяц | FJ45: =AT46 -> 0 | FN45: Вовремя/неверно сданная отчетность | FZ45: 500 | HG45: =sum(GB45:HF45)*FZ45 -> 0
D46: Кол-во оплаченных тестов | O46: 0 | T46: 0 | U46: 0 | V46: 0 | W46: 0 | X46: 1 | Y46: 0 | Z46: 0 | AA46: 1 | AB46: 1 | AC46: 0 | AE46: 1 | AF46: 0 | AK46: 1 | AL46: 0 | AM46: 0 | AN46: 0 | AQ46: 0 | AT46: =SUM(AX46:CO46) -> 0 | AX46: =(AX41*AX45)/100 -> 0 | BA46: =(BA41*BA45)/100 -> 0 | BD46: =(BD41*BD45)/100 -> 0 | BG46: =(BG41*BG45)/100 -> 0 | BJ46: =(BJ41*BJ45)/100 -> 0 | BM46: =(BM41*BM45)/100 -> 0 | BP46: =(BP41*BP45)/100 -> 0 | BS46: =(BS41*BS45)/100 -> 0 | BV46: =(BV41*BV45)/100 -> 0 | BY46: =(BY41*BY45)/100 -> 0 | CB46: =(CB41*CB45)/100 -> 0 | CE46: =(CE41*CE45)/100 -> 0 | CH46: =(CH41*CH45)/100 -> 0 | CK46: =(CK41*CK45)/100 -> 0 | CN46: =(CN41*CN45)/100 -> 0 | CR46: 2500 | CU46: Сумма продаж - личная | DH46: =SUM(O49:AR49) -> 0 | DK46: 25000 | DN46: =CR46*DT46/100 -> 0 | DQ46: =IF(DH46<DK46,DH46,IF(DH46>=DK46,DK46)) -> 0 | DT46: =DQ46*100/DK46 -> 0 | DW46: =(DK46-DH46)/'График'!AK12 -> 1086.9565 | EA46: Из одобренного теста в проданный тест | EO46: =DH43*100/DH42 -> 83.333333 | EQ46: =((DH43*100/DH42)+EO27)/2 -> 91.666667 | ET46: Премия за сумму продаж за месяц | FJ46: =if(FJ42>79,DH46*15%,if(FJ42<80,DH46*5%)) -> 0 | FN46: Опоздание без ув. причины | FZ46: 800 | HG46: =sum(GB46:HF46)*FZ46 -> 0
D47: Кол-во заключенных договоров | O47: 0 | T47: 0 | U47: 0 | V47: 0 | W47: 0 | X47: 0 | Y47: 0 | Z47: 0 | AA47: 0 | AB47: 0 | AC47: 0 | AE47: 0 | AF47: 0 | AK47: 0 | AL47: 0 | AM47: 0 | AN47: 0 | AQ47: 0 | CR47: 10000 | CU47: Сумма продаж - командный план | DH47: =sum(DH46+'Александр'!BI46) -> 0 | DK47: 70000 | DN47: =CR47*DT47/100 -> 0 | DQ47: =IF(DH47<DK47,DH47,IF(DH47>=DK47,DK47)) -> 0 | DT47: =DH47*100/DK47 -> 0 | DW47: =(DK47-DH47)/'График'!AK12 -> 3043.4783 | EA47: Из одобренного теста в заключенный договор | EO47: =DH44*100/DH42 -> 0 | EQ47: =((DH44*100/DH42)+EO28)/2 -> 20 | ET47: Зарплата без учета командного плана | FJ47: =if(FJ42>79,DH46*15%,if(FJ42<80,DH46*5%))+FJ41+FJ43+FJ44+FJ45 -> 18500 | FN47: Неявка на работу | FZ47: 1500 | HG47: =sum(GB47:HF47)*FZ47 -> 0
...

Sheet Менеджер 2
D3: Продажи | AT3: Сопровождение клиентов | CR3: Рассчеты KPI | EA3: Эффективность | ET3: Заработная плата* | FN3: Нарушения регламента работы
A4: Январь 2023 | D4: Показатели | M4: Дата | N4: 44228 | O4: 44229 | P4: 44230 | Q4: 44231 | R4: 44232 | S4: 44233 | T4: 44234 | U4: 44235 | V4: 44236 | W4: 44237 | X4: 44238 | Y4: 44239 | Z4: 44240 | AA4: 44241 | AB4: 44242 | AC4: 44243 | AD4: 44244 | AE4: 44245 | AF4: 44246 | AG4: 44247 | AH4: 44248 | AI4: 44249 | AJ4: 44250 | AK4: 44251 | AL4: 44252 | AM4: 44253 | AN4: 44254 | AO4: 44255 | AP4: 44256 | AQ4: 44257 | AR4: 44258 | AT4: Название проекта | CR4: Премия | CU4: Ключевые показатели | DH4: Факт | DK4: План | DN4: Бонус ф. | DQ4: Вып. 100% | DT4: Вып в % | DW4: Днев пл. | EA4: Ключевые конверсии | EO4: Факт* | EQ4: Ср* | ET4: Мотивация менеджера | FJ4: Сумма | FN4: Дисциплинарные нарушения | FZ4: Сумм | GB4: 44317 | GC4: 44318 | GD4: 44319 | GE4: 44320 | GF4: 44321 | GG4: 44322 | GH4: 44323 | GI4: 44324 | GJ4: 44325 | GK4: 44326 | GL4: 44327 | GM4: 44328 | GN4: 44329 | GO4: 44330 | GP4: 44331 | GQ4: 44332 | GR4: 44333 | GS4: 44334 | GT4: 44335 | GU4: 44336 | GV4: 44337 | GW4: 44338 | GX4: 44339 | GY4: 44340 | GZ4: 44341 | HA4: 44342 | HB4: 44343 | HC4: 44344 | HD4: 44345 | HE4: 44346 | HF4: 44347 | HG4: Итого
CU5: Количество новых лидов | DH5: =SUM(N8:AR8) -> 0 | DK5: 0 | DN5: =CR5*DT5/100 -> 0 | DQ5: 0 | DT5: 0 | DW5: =(DK5-DH5)/#REF! -> #REF! | EA5: Из лида в одобренный тест | EO5: =DH7*100/DH5 -> #DIV/0! | EQ5: =((DH7*100/DH5)+#REF!)/2 -> #DIV/0! | ET5: Сумма штрафов | FJ5: =HG14 -> 0
AT6: Сумма | AX6: 25000 | CU6: Количество результативных звонков | DH6: =SUM(N9:AR9) -> 0 | DK6: 80 | DN6: =CR6*DT6/100 -> 0 | DQ6: =IF(DH6<DK6,DH6,IF(DH6>=DK6,DK6)) -> 0 | DT6: =DQ6*100/DK6 -> 0 | DW6: =(DK6-DH6)/#REF! -> #REF! | EA6: Из лида в оплаченный тест | EO6: =DH8*100/DH5 -> #DIV/0! | EQ6: =((DH7*100/DH5)+#REF!)/2 -> #DIV/0! | ET6: Бонус за выполнение KPI | FJ6: =sum(DN8,DN9,DN11) -> 0
AT7: Количество | AX7: 1 | CU7: Кол-во одобренных тестов | DH7: =SUM(N10:AR10) -> 0 | DK7: 5 | DN7: =CR7*DT7/100 -> 0 | DQ7: =IF(DH7<DK7,DH7,IF(DH7>=DK7,DK7)) -> 0 | DT7: =DQ7*100/DK7 -> 0 | DW7: =(DK7-DH7)/#REF! -> #REF! | EA7: Из лида в заключенный договор | EO7: =DH9*100/DH5 -> #DIV/0! | EQ7: =((DH9*100/DH5)+#REF!)/2 -> #DIV/0! | ET7: Общий % выполнения KPI | FJ7: =sum(DT8,DT9,DT11)/3 -> 0
D8: Кол-во новых лидов | AT8: 2 месяц | AW8: % | AX8: 10 | BA8: 10 | BD8: 10 | BG8: 10 | BJ8: 10 | BM8: 10 | BP8: 10 | BS8: 10 | BV8: 10 | BY8: 10 | CB8: 10 | CE8: 10 | CH8: 10 | CK8: 10 | CN8: 10 | CR8: 10000 | CU8: Кол-во оплаченных тестов | DH8: =SUM(N11:AR11) -> 0 | DK8: 5 | DN8: =CR8*DT8/100 -> 0 | DQ8: =IF(DH8<DK8,DH8,IF(DH8>=DK8,DK8)) -> 0 | DT8: =DQ8*100/DK8 -> 0 | DW8: =(DK8-DH8)/#REF! -> #REF! | EA8: Из результативного звонка в одобренный тест | EO8: =DH7*100/DH6 -> #DIV/0! | EQ8: =((DH7*100/DH6)+#REF!)/2 -> #DIV/0! | ET8: Премия за платные тесты | FJ8: =sum(AX17:CP17) -> 0 | FN8: Ведение CRM | FZ8: 200 | HG8: =sum(GB8:HF8)*FZ8 -> 0
D9: Кол-во результативных звонков | AT9: =SUM(AX9:CO9) -> 2500 | AX9: =(AX6*AX8)/100 -> 2500 | BA9: =(BA6*BA8)/100 -> 0 | BD9: =(BD6*BD8)/100 -> 0 | BG9: =(BG6*BG8)/100 -> 0 | BJ9: =(BJ6*BJ8)/100 -> 0 | BM9: =(BM6*BM8)/100 -> 0 | BP9: =(BP6*BP8)/100 -> 0 | BS9: =(BS6*BS8)/100 -> 0 | BV9: =(BV6*BV8)/100 -> 0 | BY9: =(BY6*BY8)/100 -> 0 | CB9: =(CB6*CB8)/100 -> 0 | CE9: =(CE6*CE8)/100 -> 0 | CH9: =(CH6*CH8)/100 -> 0 | CK9: =(CK6*CK8)/100 -> 0 | CN9: =(CN6*CN8)/100 -> 0 | CR9: 2500 | CU9: Кол-во заключенных договоров | DH9: =SUM(N12:AR12) -> 0 | DK9: 2 | DN9: =CR9*DT9/100 -> 0 | DQ9: =IF(DH9<DK9,DH9,IF(DH9>=DK9,DK9)) -> 0 | DT9: =DQ9*100/DK9 -> 0 | DW9: =(DK9-DH9)/#REF! -> #REF! | EA9: Из звонка в проведенный тест | EO9: =DH8*100/DH6 -> #DIV/0! | EQ9: =((DH8*100/DH6)+#REF!)/2 -> #DIV/0! | ET9: Премия за сопровождение проектов за второй месяц | FJ9: =AT9 -> 2500 | FN9: Соблюдение регламентов и скриптов | FZ9: 200 | HG9: =sum(GB9:HF9)*FZ9 -> 0
D10: Кол-во одобренных тестов | AT10: 3 месяц | AW10: % | BA10: 5 | BD10: 5 | BG10: 5 | BJ10: 5 | BM10: 5 | BP10: 5 | BS10: 5 | BV10: 5 | BY10: 5 | CB10: 5 | CE10: 5 | CH10: 5 | CK10: 5 | CN10: 5 | CU10: Кол-во позиций в договоре | DH10: =SUM(N13:AR13) -> 0 | DK10: 0 | DN10: =CR10*DT10/100 -> 0 | DQ10: 0 | DT10: 0 | DW10: =(DK10-DH10)/#REF! -> #REF! | EA10: Из звонка в заключенный договор | EO10: =DH9*100/DH6 -> #DIV/0! | EQ10: =((DH9*100/DH6)+#REF!)/2 -> #DIV/0! | ET10: Премия за сопровождение проектов за третий месяц | FJ10: =AT11 -> 0 | FN10: Вовремя/неверно сданная отчетность | FZ10: 500 | HG10: =sum(GB10:HF10)*FZ10 -> 0
D11: Кол-во оплаченных тестов | AT11: =SUM(AX11:CO11) -> 0 | AX11: =(AX6*AX10)/100 -> 0 | BA11: =(BA6*BA10)/100 -> 0 | BD11: =(BD6*BD10)/100 -> 0 | BG11: =(BG6*BG10)/100 -> 0 | BJ11: =(BJ6*BJ10)/100 -> 0 | BM11: =(BM6*BM10)/100 -> 0 | BP11: =(BP6*BP10)/100 -> 0 | BS11: =(BS6*BS10)/100 -> 0 | BV11: =(BV6*BV10)/100 -> 0 | BY11: =(BY6*BY10)/100 -> 0 | CB11: =(CB6*CB10)/100 -> 0 | CE11: =(CE6*CE10)/100 -> 0 | CH11: =(CH6*CH10)/100 -> 0 | CK11: =(CK6*CK10)/100 -> 0 | CN11: =(CN6*CN10)/100 -> 0 | CR11: 2500 | CU11: Сумма продаж - личная | DH11: =SUM(O14:AR14) -> 0 | DK11: 40000 | DN11: =CR11*DT11/100 -> 0 | DQ11: =IF(DH11<DK11,DH11,IF(DH11>=DK11,DK11)) -> 0 | DT11: =DQ11*100/DK11 -> 0 | DW11: =(DK11-DH11)/#REF! -> #REF! | EA11: Из одобренного теста в проданный тест | EO11: =DH8*100/DH7 -> #DIV/0! | EQ11: =((DH8*100/DH7)+#REF!)/2 -> #DIV/0! | ET11: Премия за сумму продаж за месяц | FJ11: =if(FJ7>79,DH11*15%,if(FJ7<80,DH11*5%)) -> 0 | FN11: Опоздание без ув. причины | FZ11: 800 | HG11: =sum(GB11:HF11)*FZ11 -> 0
D12: Кол-во заключенных договоров | CR12: 10000 | CU12: Сумма продаж - командный план | DH12: =sum(DH11) -> 0 | DK12: 80000 | DN12: =CR12*DT12/100 -> 0 | DQ12: =IF(DH12<DK12,DH12,IF(DH12>=DK12,DK12)) -> 0 | DT12: =DH12*100/DK12 -> 0 | DW12: =(DK12-DH12)/#REF! -> #REF! | EA12: Из одобренного теста в заключенный договор | EO12: =DH9*100/DH7 -> #DIV/0! | EQ12: =((DH9*100/DH7)+#REF!)/2 -> #DIV/0! | ET12: Зарплата без учета командного плана | FJ12: =if(FJ7>79,DH11*15%,if(FJ7<80,DH11*5%))+FJ6+FJ8+FJ9+FJ10 -> 2500 | FN12: Неявка на работу | FZ12: 1500 | HG12: =sum(GB12:HF12)*FZ12 -> 0
D13: Кол-во позиций в договоре | AT13: Платные тесты | CU13: Сумма продаж - тесты | DH13: =sum(AX16:CP16) -> 0 | DK13: 0 | DN13: =CR13*DT13/100 -> #DIV/0! | DQ13: =IF(DH13<DK13,DH13,IF(DH13>=DK13,DK13)) -> 0 | DT13: =DH13*100/DK13 -> #DIV/0! | DW13: =(DK13-DH13)/#REF! -> #REF! | EA13: Из теста в заключенный договор | EO13: =DH9*100/DH8 -> #DIV/0! | EQ13: =((DH9*100/DH8)+#REF!)/2 -> #DIV/0! | ET13: Итого | FJ13: =if(DH12>=DK12,FJ12+CR12,if(DH12<DK12,FJ12))-HG14 -> 2500 | FN13: Неверно составленное ТЗ | FZ13: 1000 | HG13: =sum(GB13:HF13)*FZ13 -> 0
D14: Сумма продаж | AT14: Название проекта | CU14: Сумма продаж - общая | DH14: =sum(DH11+DH13) -> 0 | DK14: 0 | DN14: =CR14*DT14/100 -> #DIV/0! | DQ14: =IF(DH14<DK14,DH14,IF(DH14>=DK14,DK14)) -> 0 | DT14: =DH14*100/DK14 -> #DIV/0! | DW14: =(DK14-DH14)/#REF! -> #REF! | HE14: Итого | HG14: =sum(HG8:HG13) -> 0
CU15: Средний чек | DH15: =DH11/DH9 -> #DIV/0! | DK15: 25000 | DN15: =CR15*DT15/100 -> #DIV/0! | DQ15: =IF(DH15<DK15,DH15,IF(DH15>=DK15,DK15)) -> #DIV/0! | DT15: =DH15*100/DK15 -> #DIV/0! | DW15: =(DK15-DH15)/#REF! -> #DIV/0!
AT16: Сумма | CU16: Среднее количество позиций в договоре | DH16: =(DH9/DH10) -> #DIV/0! | DK16: 0 | DN16: =CR16*DT16/100 -> #DIV/0! | DQ16: =IF(DH16<DK16,DH16,IF(DH16>=DK16,DK16)) -> #DIV/0! | DT16: =DH16*100/DK16 -> #DIV/0! | DW16: =(DK16-DH16)/#REF! -> #DIV/0!
AT17: 20 | AW17: % | AX17: =AX16*AT17/100 -> 0 | BA17: =BA16*AT17/100 -> 0 | BD17: =BD16*AT17/100 -> 0 | BG17: =BG16*AT17/100 -> 0 | BJ17: =BJ16*AT17/100 -> 0 | BM17: =BM16*AT17/100 -> 0 | BP17: =BP16*AT17/100 -> 0 | BS17: =BS16*AT17/100 -> 0 | BV17: =BV16*AT17/100 -> 0 | BY17: =BY16*HH16/100 -> 0 | CB17: =CB16*AT17/100 -> 0 | CE17: =CE16*AT17/100 -> 0 | CH17: =CH16*AT17/100 -> 0 | CK17: =CK16*AT17/100 -> 0 | CN17: =CN16*AT17/100 -> 0 | CR17: =sum(CR5:CT11,CR13,CR14,CR15,CR16) -> 15000 | CU17: Общий % выполнения KPI | DH17: =sum(DT8,DT9,DT11)/3 -> 0 | DK17: 100 | DN17: =sum(DN8,DN9,DN11) -> 0 | DQ17: =IF(DH17<DK17,DH17,IF(DH17>=DK17,DK17)) -> 0 | DT17: =DH17*100/DK17 -> 0 | DW17: =(DK17-DH17)/#REF! -> #REF!
D21: Продажи | AT21: Сопровождение клиентов | CR21: Рассчеты KPI | EA21: Эффективность | ET21: Заработная плата* | FN21: Нарушения регламента работы
A22: Январь 2023 | D22: Показатели | M22: Дата | N22: 44228 | O22: 44229 | P22: 44230 | Q22: 44231 | R22: 44232 | S22: 44233 | T22: 44234 | U22: 44235 | V22: 44236 | W22: 44237 | X22: 44238 | Y22: 44239 | Z22: 44240 | AA22: 44241 | AB22: 44242 | AC22: 44243 | AD22: 44244 | AE22: 44245 | AF22: 44246 | AG22: 44247 | AH22: 44248 | AI22: 44249 | AJ22: 44250 | AK22: 44251 | AL22: 44252 | AM22: 44253 | AN22: 44254 | AO22: 44255 | AP22: 44256 | AQ22: 44257 | AR22: 44258 | AT22: Название проекта | CR22: Премия | CU22: Ключевые показатели | DH22: Факт | DK22: План | DN22: Бонус ф. | DQ22: Вып. 100% | DT22: Вып в % | DW22: Днев пл. | EA22: Ключевые конверсии | EO22: Факт* | EQ22: Ср* | ET22: Мотивация менеджера | FJ22: Сумма | FN22: Дисциплинарные нарушения | FZ22: Сумм | GB22: 44317 | GC22: 44318 | GD22: 44319 | GE22: 44320 | GF22: 44321 | GG22: 44322 | GH22: 44323 | GI22: 44324 | GJ22: 44325 | GK22: 44326 | GL22: 44327 | GM22: 44328 | GN22: 44329 | GO22: 44330 | GP22: 44331 | GQ22: 44332 | GR22: 44333 | GS22: 44334 | GT22: 44335 | GU22: 44336 | GV22: 44337 | GW22: 44338 | GX22: 44339 | GY22: 44340 | GZ22: 44341 | HA22: 44342 | HB22: 44343 | HC22: 44344 | HD22: 44345 | HE22: 44346 | HF22: 44347 | HG22: Итого
CR23: 2000 | CU23: Количество новых лидов взятых в работу | DH23: =SUM(N26:AR26) -> 40 | DK23: 40 | DN23: =CR23*DT23/100 -> 2000 | DQ23: =IF(DH23<DK23,DH23,IF(DH23>=DK23,DK23)) -> 40 | DT23: =DQ23*100/DK23 -> 100 | DW23: =(DK23-DH23)/#REF! -> #REF! | EA23: Из лида в одобренный тест | EO23: =DH25*100/DH23 -> 50 | EQ23: =((DH25*100/DH23)+#REF!)/2 -> #REF! | ET23: Сумма штрафов | FJ23: =HG32 -> 0
AT24: Сумма | AX24: 220000 | CU24: Количество результативных звонков | DH24: =SUM(N27:AR27) -> 40 | DK24: 80 | DN24: =CR24*DT24/100 -> 0 | DQ24: =IF(DH24<DK24,DH24,IF(DH24>=DK24,DK24)) -> 40 | DT24: =DQ24*100/DK24 -> 50 | DW24: =(DK24-DH24)/#REF! -> #REF! | EA24: Из лида в оплаченный тест | EO24: =DH26*100/DH23 -> 12.5 | EQ24: =((DH25*100/DH23)+#REF!)/2 -> #REF! | ET24: Бонус за выполнение KPI | FJ24: =sum(DN26,DN27,DN29) -> 10000
AT25: Количество | AX25: 1 | CU25: Кол-во одобренных тестов | DH25: =SUM(N28:AR28) -> 20 | DK25: 5 | DN25: =CR25*DT25/100 -> 0 | DQ25: =IF(DH25<DK25,DH25,IF(DH25>=DK25,DK25)) -> 5 | DT25: =DQ25*100/DK25 -> 100 | DW25: =(DK25-DH25)/#REF! -> #REF! | EA25: Из лида в заключенный договор | EO25: =DH27*100/DH23 -> 5 | EQ25: =((DH27*100/DH23)+#REF!)/2 -> #REF! | ET25: Общий % выполнения KPI | FJ25: =sum(DT26,DT27,DT29)/3 -> 100
D26: Кол-во новых лидов | Z26: 40 | AT26: 2 месяц | AW26: % | AX26: 10 | BA26: 10 | BD26: 10 | BG26: 10 | BJ26: 10 | BM26: 10 | BP26: 10 | BS26: 10 | BV26: 10 | BY26: 10 | CB26: 10 | CE26: 10 | CH26: 10 | CK26: 10 | CN26: 10 | CR26: 5000 | CU26: Кол-во оплаченных тестов | DH26: =SUM(N29:AR29) -> 5 | DK26: 5 | DN26: =CR26*DT26/100 -> 5000 | DQ26: =IF(DH26<DK26,DH26,IF(DH26>=DK26,DK26)) -> 5 | DT26: =DQ26*100/DK26 -> 100 | DW26: =(DK26-DH26)/#REF! -> #REF! | EA26: Из результативного звонка в одобренный тест | EO26: =DH25*100/DH24 -> 50 | EQ26: =((DH25*100/DH24)+#REF!)/2 -> #REF! | ET26: Премия за платные тесты | FJ26: =sum(AX35:CP35) -> 15000 | FN26: Ведение CRM | FZ26: 200 | HG26: =sum(GB26:HF26)*FZ26 -> 0
D27: Кол-во результативных звонков | Z27: 40 | AT27: =SUM(AX27:CO27) -> 22000 | AX27: =(AX24*AX26)/100 -> 22000 | BA27: =(BA24*BA26)/100 -> 0 | BD27: =(BD24*BD26)/100 -> 0 | BG27: =(BG24*BG26)/100 -> 0 | BJ27: =(BJ24*BJ26)/100 -> 0 | BM27: =(BM24*BM26)/100 -> 0 | BP27: =(BP24*BP26)/100 -> 0 | BS27: =(BS24*BS26)/100 -> 0 | BV27: =(BV24*BV26)/100 -> 0 | BY27: =(BY24*BY26)/100 -> 0 | CB27: =(CB24*CB26)/100 -> 0 | CE27: =(CE24*CE26)/100 -> 0 | CH27: =(CH24*CH26)/100 -> 0 | CK27: =(CK24*CK26)/100 -> 0 | CN27: =(CN24*CN26)/100 -> 0 | CR27: 2500 | CU27: Кол-во заключенных договоров | DH27: =SUM(N30:AR30) -> 2 | DK27: 2 | DN27: =CR27*DT27/100 -> 2500 | DQ27: =IF(DH27<DK27,DH27,IF(DH27>=DK27,DK27)) -> 2 | DT27: =DQ27*100/DK27 -> 100 | DW27: =(DK27-DH27)/#REF! -> #REF! | EA27: Из звонка в проведенный тест | EO27: =DH26*100/DH24 -> 12.5 | EQ27: =((DH26*100/DH24)+#REF!)/2 -> #REF! | ET27: Премия за сопровождение проектов за второй месяц | FJ27: =AT27 -> 22000 | FN27: Соблюдение регламентов и скриптов | FZ27: 200 | HG27: =sum(GB27:HF27)*FZ27 -> 0
D28: Кол-во одобренных тестов | Z28: 20 | AT28: 3 месяц | AW28: % | BA28: 5 | BD28: 5 | BG28: 5 | BJ28: 5 | BM28: 5 | BP28: 5 | BS28: 5 | BV28: 5 | BY28: 5 | CB28: 5 | CE28: 5 | CH28: 5 | CK28: 5 | CN28: 5 | CU28: Кол-во позиций в договоре | DH28: =SUM(N31:AR31) -> 3 | DK28: 0 | DN28: =CR28*DT28/100 -> 0 | DQ28: 0 | DT28: 0 | DW28: =(DK28-DH28)/#REF! -> #REF! | EA28: Из звонка в заключенный договор | EO28: =DH27*100/DH24 -> 5 | EQ28: =((DH27*100/DH24)+#REF!)/2 -> #REF! | ET28: Премия за сопровождение проектов за третий месяц | FJ28: =AT29 -> 0 | FN28: Вовремя/неверно сданная отчетность | FZ28: 500 | HG28: =sum(GB28:HF28)*FZ28 -> 0
D29: Кол-во оплаченных тестов | Z29: 5 | AT29: =SUM(AX29:CO29) -> 0 | AX29: =(AX24*AX28)/100 -> 0 | BA29: =(BA24*BA28)/100 -> 0 | BD29: =(BD24*BD28)/100 -> 0 | BG29: =(BG24*BG28)/100 -> 0 | BJ29: =(BJ24*BJ28)/100 -> 0 | BM29: =(BM24*BM28)/100 -> 0 | BP29: =(BP24*BP28)/100 -> 0 | BS29: =(BS24*BS28)/100 -> 0 | BV29: =(BV24*BV28)/100 -> 0 | BY29: =(BY24*BY28)/100 -> 0 | CB29: =(CB24*CB28)/100 -> 0 | CE29: =(CE24*CE28)/100 -> 0 | CH29: =(CH24*CH28)/100 -> 0 | CK29: =(CK24*CK28)/100 -> 0 | CN29: =(CN24*CN28)/100 -> 0 | CR29: 2500 | CU29: Сумма продаж - личная | DH29: =SUM(O32:AR32) -> 50000 | DK29: 40000 | DN29: =CR29*DT29/100 -> 2500 | DQ29: =IF(DH29<DK29,DH29,IF(DH29>=DK29,DK29)) -> 40000 | DT29: =DQ29*100/DK29 -> 100 | DW29: =(DK29-DH29)/#REF! -> #REF! | EA29: Из одобренного теста в проданный тест | EO29: =DH26*100/DH25 -> 25 | EQ29: =((DH26*100/DH25)+#REF!)/2 -> #REF! | ET29: Премия за сумму продаж за месяц | FJ29: =if(FJ25>79,DH29*15%,if(FJ25<80,DH29*5%)) -> 7500 | FN29: Опоздание без ув. причины | FZ29: 800 | HG29: =sum(GB29:HF29)*FZ29 -> 0
D30: Кол-во заключенных договоров | Z30: 2 | CR30: 10000 | CU30: Сумма продаж - командный план | DH30: =sum(DH29) -> 50000 | DK30: 80000 | DN30: =CR30*DT30/100 -> 6250 | DQ30: =IF(DH30<DK30,DH30,IF(DH30>=DK30,DK30)) -> 50000 | DT30: =DH30*100/DK30 -> 62.5 | DW30: =(DK30-DH30)/#REF! -> #REF! | EA30: Из одобренного теста в заключенный договор | EO30: =DH27*100/DH25 -> 10 | EQ30: =((DH27*100/DH25)+#REF!)/2 -> #REF! | ET30: Зарплата без учета командного плана | FJ30: =if(FJ25>79,DH29*15%,if(FJ25<80,DH29*5%))+FJ24+FJ26+FJ27+FJ28 -> 54500 | FN30: Неявка на работу | FZ30: 1500 | HG30: =sum(GB30:HF30)*FZ30 -> 0
D31: Кол-во позиций в договоре | Z31: 3 | AT31: Платные тесты | CR31: 2500 | CU31: Сумма продаж - тесты | DH31: =sum(AX34:CP34) -> 75000 | DK31: 75000 | DN31: =CR31*DT31/100 -> 2500 | DQ31: =IF(DH31<DK31,DH31,IF(DH31>=DK31,DK31)) -> 75000 | DT31: =DH31*100/DK31 -> 100 | DW31: =(DK31-DH31)/#REF! -> #REF! | EA31: Из теста в заключенный договор | EO31: =DH27*100/DH26 -> 40 | EQ31: =((DH27*100/DH26)+#REF!)/2 -> #REF! | ET31: Итого | FJ31: =if(DH30>=DK30,FJ30+CR30,if(DH30<DK30,FJ30))-HG32 -> 54500 | FN31: Неверно составленное ТЗ | FZ31: 1000 | HG31: =sum(GB31:HF31)*FZ31 -> 0
D32: Сумма продаж | Z32: 50000 | AT32: Название проекта | CR32: 2500 | CU32: Сумма продаж - общая | DH32: =sum(DH29+DH31) -> 125000 | DK32: 150000 | DN32: =CR32*DT32/100 -> 2083.3333 | DQ32: =IF(DH32<DK32,DH32,IF(DH32>=DK32,DK32)) -> 125000 | DT32: =DH32*100/DK32 -> 83.333333 | DW32: =(DK32-DH32)/#REF! -> #REF! | HE32: Итого | HG32: =sum(HG26:HG31) -> 0
CR33: 1000 | CU33: Средний чек | DH33: =DH29/DH27 -> 25000 | DK33: 25000 | DN33: =CR33*DT33/100 -> 1000 | DQ33: =IF(DH33<DK33,DH33,IF(DH33>=DK33,DK33)) -> 25000 | DT33: =DH33*100/DK33 -> 100 | DW33: =(DK33-DH33)/#REF! -> #REF!
AT34: Сумма | AX34: 10000 | BA34: 10000 | BD34: 10000 | BG34: 10000 | BJ34: 5000 | BM34: 10000 | BP34: 10000 | BS34: 10000 | CR34: 2000 | CU34: Среднее количество позиций в договоре | DH34: =(DH28/DH27) -> 1.5 | DK34: 45047 | DN34: =CR34*DT34/100 -> 0.06659711 | DQ34: =IF(DH34<DK34,DH34,IF(DH34>=DK34,DK34)) -> 1.5 | DT34: =DH34*100/DK34 -> 0.0033298555 | DW34: =(DK34-DH34)/#REF! -> #REF!
AT35: 20 | AW35: % | AX35: =AX34*AT35/100 -> 2000 | BA35: =BA34*AT35/100 -> 2000 | BD35: =BD34*AT35/100 -> 2000 | BG35: =BG34*AT35/100 -> 2000 | BJ35: =BJ34*AT35/100 -> 1000 | BM35: =BM34*AT35/100 -> 2000 | BP35: =BP34*AT35/100 -> 2000 | BS35: =BS34*AT35/100 -> 2000 | BV35: =BV34*AT35/100 -> 0 | BY35: =BY34*HH34/100 -> 0 | CB35: =CB34*AT35/100 -> 0 | CE35: =CE34*AT35/100 -> 0 | CH35: =CH34*AT35/100 -> 0 | CK35: =CK34*AT35/100 -> 0 | CN35: =CN34*AT35/100 -> 0 | CR35: =sum(CR23:CT29,CR31,CR32,CR33,CR34) -> 20000 | CU35: Общий % выполнения KPI | DH35: =sum(DT23,DT26,DT27,DT29,DT31,DT32,DT33,DT34)/8 -> 85.417083 | DK35: 100 | DN35: =sum(DN23,DN26,DN27,DN29,DN31,DN33,DN34,DN35) -> #REF! | DQ35: =IF(DH35<DK35,DH35,IF(DH35>=DK35,DK35)) -> 85.417083 | DT35: =DH35*100/DK35 -> 85.417083 | DW35: =(DK35-DH35)/#REF! -> #REF!

Sheet Александр
C3: Продажи | AS3: Рассчеты | BY3: Эффективность | CR3: Заработная плата | DL3: Нарушения регламента работы | FI3: Сопровождение клиентов
A4: Январь 2022 | C4: Показатели | L4: Дата | M4: 44531 | N4: 44532 | O4: 44533 | P4: 44534 | Q4: 44535 | R4: 44536 | S4: 44537 | T4: 44538 | U4: 44539 | V4: 44540 | W4: 44541 | X4: 44542 | Y4: 44543 | Z4: 44544 | AA4: 44545 | AB4: 44546 | AC4: 44547 | AD4: 44548 | AE4: 44549 | AF4: 44550 | AG4: 44551 | AH4: 44552 | AI4: 44553 | AJ4: 44554 | AK4: 44555 | AL4: 44556 | AM4: 44557 | AN4: 44558 | AO4: 44559 | AP4: 44560 | AQ4: 44561 | AS4: Ключевые показатели | BF4: Факт | BI4: План | BL4: Вып 100% | BO4: Бонус | BR4: Вып в % | BU4: Днев ПЛ | BY4: Ключевые конверсии | CM4: Факт | CO4: Сред | CR4: Мотивация менеджера | DH4: Сумма | DL4: Дисциплинарные нарушения | DX4: Сумм | DZ4: 44531 | EA4: 44532 | EB4: 44533 | EC4: 44534 | ED4: 44535 | EE4: 44536 | EF4: 44537 | EG4: 44538 | EH4: 44539 | EI4: 44540 | EJ4: 44541 | EK4: 44542 | EL4: 44543 | EM4: 44544 | EN4: 44545 | EO4: 44546 | EP4: 44547 | EQ4: 44548 | ER4: 44549 | ES4: 44550 | ET4: 44551 | EU4: 44552 | EV4: 44553 | EW4: 44554 | EX4: 44555 | EY4: 44556 | EZ4: 44557 | FA4: 44558 | FB4: 44559 | FC4: 44560 | FD4: 44561 | FE4: Итого | FI4: Название проекта | FM4: Находка АкадемияМебели | FP4: Тамбов Пилот | FS4: Ульяновск Шарли | FV4: Казань ИльнарКух
AS5: Количество новых лидов | BF5: =SUM(M8:AQ8) -> 0 | BI5: 50 | BL5: 0 | BO5: 0 | BR5: 0 | BU5: =(BI5-BF5)/'График'!AK4 -> 2.173913 | BY5: Из лида в одобренный тест | CM5: =BF7*100/BF5 -> #DIV/0! | CR5: Сумма штрафов | DH5: =FE14 -> 0
AS6: Количество результативных звонков | BF6: =SUM(M9:AQ9) -> 0 | BI6: 50 | BL6: =IF(BF6<BI6,BF6,IF(BF6>=BI6,BI6)) -> 0 | BO6: =2500*BR6/100 -> 0 | BR6: =BL6*100/BI6 -> 0 | BU6: =(BI6-BF6)/'График'!AK4 -> 2.173913 | BY6: Из лида в оплаченный тест | CM6: =BF8*100/BF5 -> #DIV/0! | CR6: Бонус за выполнение KPI | DH6: =sum(BO6:BQ9,BO11) -> 0 | FI6: Сумма | FM6: 20000 | FP6: 20000 | FS6: 20000 | FV6: 15000
AS7: Кол-во одобренных тестов | BF7: =SUM(M10:AQ10) -> 0 | BI7: 40 | BL7: =IF(BF7<BI7,BF7,IF(BF7>=BI7,BI7)) -> 0 | BO7: =2500*BR7/100 -> 0 | BR7: =BL7*100/BI7 -> 0 | BU7: =(BI7-BF7)/'График'!AK4 -> 1.7391304 | BY7: Из лида в заключенный договор | CM7: =BF9*100/BF5 -> #DIV/0! | CR7: Общий % выполнения KPI | DH7: =sum(BR6,BR7,BR8,BR9,BR11)/5 -> 0 | FI7: Количество | FM7: 1 | FP7: 1 | FS7: 3 | FV7: 4 | FY7: 5 | GB7: 6 | GE7: 7 | GH7: 8 | GK7: 9 | GN7: 10 | GQ7: 11 | GT7: 12 | GW7: 13 | GZ7: 14 | HC7: 15
C8: Кол-во новых лидов | AS8: Кол-во оплаченных тестов | BF8: =SUM(M11:AQ11) -> 0 | BI8: 30 | BL8: =IF(BF8<BI8,BF8,IF(BF8>=BI8,BI8)) -> 0 | BO8: =2500*BR8/100 -> 0 | BR8: =BL8*100/BI8 -> 0 | BU8: =(BI8-BF8)/'График'!AK4 -> 1.3043478 | BY8: Из результативного звонка в одобренный тест | CM8: =BF7*100/BF6 -> #DIV/0! | CR8: Премия за сопровождение проектов за второй месяц | DL8: Ведение CRM | DX8: 200 | FE8: =sum(DZ8:FD8)*DX8 -> 0 | FI8: 2 месяц | FL8: % | FM8: 10 | FP8: 10 | FS8: 10 | FV8: 10 | FY8: 10 | GB8: 10 | GE8: 10 | GH8: 10 | GK8: 10 | GN8: 10 | GQ8: 10 | GT8: 10 | GW8: 10 | GZ8: 10 | HC8: 10
C9: Кол-во результативных звонков | AS9: Кол-во заключенных договоров | BF9: =SUM(M12:AQ12) -> 0 | BI9: 4 | BL9: =IF(BF9<BI9,BF9,IF(BF9>=BI9,BI9)) -> 0 | BO9: =2500*BR9/100 -> 0 | BR9: =BL9*100/BI9 -> 0 | BU9: =(BI9-BF9)/'График'!AK4 -> 0.17391304 | BY9: Из звонка в проведенный тест | CM9: =BF8*100/BF6 -> #DIV/0! | CR9: Премия за сопровождение проектов за третий месяц | DL9: Соблюдение регламентов и скриптов | DX9: 200 | FE9: =sum(DZ9:FD9)*DX9 -> 0 | FI9: =SUM(FM9:HD9) -> 7500 | FM9: =(FM6*FM8)/100 -> 2000 | FP9: =(FP6*FP8)/100 -> 2000 | FS9: =(FS6*FS8)/100 -> 2000 | FV9: =(FV6*FV8)/100 -> 1500 | FY9: =(FY6*FY8)/100 -> 0 | GB9: =(GB6*GB8)/100 -> 0 | GE9: =(GE6*GE8)/100 -> 0 | GH9: =(GH6*GH8)/100 -> 0 | GK9: =(GK6*GK8)/100 -> 0 | GN9: =(GN6*GN8)/100 -> 0 | GQ9: =(GQ6*GQ8)/100 -> 0 | GT9: =(GT6*GT8)/100 -> 0 | GW9: =(GW6*GW8)/100 -> 0 | GZ9: =(GZ6*GZ8)/100 -> 0 | HC9: =(HC6*HC8)/100 -> 0
C10: Кол-во одобренных тестов | AS10: Кол-во позиций в договоре | BF10: =SUM(M13:AQ13) -> 0 | BI10: 4 | BL10: 0 | BO10: 0 | BR10: 0 | BU10: =(BI10-BF10)/'График'!AK4 -> 0.17391304 | BY10: Из звонка в заключенный договор | CM10: =BF9*100/BF6 -> #DIV/0! | CR10: Зарплата менеджера без учета командного плана | DH10: =if(DH7>84,BF11*15%+DH6,if(DH7<85,BF11*5%+DH6)) -> 0 | DL10: Вовремя/неверно сданная отчетность | DX10: 500 | FE10: =sum(DZ10:FD10)*DX10 -> 0 | FI10: 3 месяц | FL10: % | FV10: 10 | FY10: 10 | GB10: 10 | GE10: 10 | GH10: 10 | GK10: 10 | GN10: 10 | GQ10: 10 | GT10: 10 | GW10: 10 | GZ10: 10 | HC10: 10
C11: Кол-во оплаченных тестов | AS11: Сумма продаж | BF11: =SUM(M14:AQ14) -> 0 | BI11: 80000 | BL11: =IF(BF11<BI11,BF11,IF(BF11>=BI11,BI11)) -> 0 | BO11: =5000*BR11/100 -> 0 | BR11: =BL11*100/BI11 -> 0 | BU11: =(BI11-BF11)/'График'!AK4 -> 3478.2609 | BY11: Из одобренного теста в проведенный тест | CM11: =BF8*100/BF7 -> #DIV/0! | CR11: Зарплата менеджера с учетом командного плана | DH11: =if(BF12>=BI12,DH10+BO12,if(BF12<BI12,DH10))-FE14 -> 0 | DL11: Опоздание без ув. причины | DX11: 800 | FE11: =sum(DZ11:FD11)*DX11 -> 0 | FI11: =SUM(FM11:HD11) -> 1500 | FM11: =(FM6*FM10)/100 -> 0 | FP11: =(FP6*FP10)/100 -> 0 | FS11: =(FS6*FS10)/100 -> 0 | FV11: =(FV6*FV10)/100 -> 1500 | FY11: =(FY6*FY10)/100 -> 0 | GB11: =(GB6*GB10)/100 -> 0 | GE11: =(GE6*GE10)/100 -> 0 | GH11: =(GH6*GH10)/100 -> 0 | GK11: =(GK6*GK10)/100 -> 0 | GN11: =(GN6*GN10)/100 -> 0 | GQ11: =(GQ6*GQ10)/100 -> 0 | GT11: =(GT6*GT10)/100 -> 0 | GW11: =(GW6*GW10)/100 -> 0 | GZ11: =(GZ6*GZ10)/100 -> 0 | HC11: =(HC6*HC10)/100 -> 0
C12: Кол-во заключенных договоров | AS12: Командный план | BF12: =sum(BF11+'Евгений Ж.'!DH9) -> 0 | BI12: 80000 | BO12: 10000 | BR12: =BF12*100/BI12 -> 0 | BU12: =(BI12-BF12)/'График'!AK4 -> 3478.2609 | BY12: Из одобренного теста в заключенный договор | CM12: =BF9*100/BF7 -> #DIV/0! | DF12: Итого | DH12: =sum(DH11+DH8+DH9) -> 0 | DL12: Неявка на работу | DX12: 1500 | FE12: =sum(DZ12:FD12)*DX12 -> 0 | FI12: Платные тесты
C13: Кол-во позиций в договоре | AS13: Остаток до выполнения личного плана | BF13: =BI11-BF11 -> 80000 | BY13: Из теста в заключенный договор | CM13: =BF9*100/BF8 -> #DIV/0! | DL13: Неверно составленное ТЗ | DX13: 1000 | FE13: =sum(DZ13:FD13)*DX13 -> 0 | FI13: Название проекта | FM13: Название Проекта | FP13: Тюмень Мебельщик | FS13: Иркутск Мебелевич | FV13: Омск КитМебель | FY13: Казань Коновалов | GB13: Казань Давинчи | GE13: Архангельск Евромебель | GH13: Казань Шарли | GK13: Название Проекта | GN13: Название Проекта | GQ13: Название Проекта | GT13: Название Проекта | GW13: Название Проекта | GZ13: Название Проекта | HC13: Название Проекта
C14: Сумма продаж | AS14: Средний чек | BF14: =BF11/BF9 -> #DIV/0! | FC14: Итого | FE14: =sum(FE8:FE13) -> 0
AS15: Общее количество звонков | FI15: Сумма | FM15: 2000 | FP15: 1000 | FS15: 5000 | FV15: 1000 | FY15: 1000 | GB15: 2000 | GE15: 1000 | GH15: 3000
AS16: Общее количество минут разговора | FI16: 20 | FL16: % | FM16: =FM15*FI16/100 -> 400 | FP16: =FP15*FI16/100 -> 200 | FS16: =FS15*FI16/100 -> 1000 | FV16: =FV15*FI16/100 -> 200 | FY16: =FY15*FI16/100 -> 200 | GB16: =GB15*FI16/100 -> 400 | GE16: =GE15*FI16/100 -> 200 | GH16: =GH15*FI16/100 -> 600 | GK16: =GK15*FI16/100 -> 0 | GN16: =GN15*FI16/100 -> 0 | GQ16: =GQ15*FI16/100 -> 0 | GT16: =GT15*FI16/100 -> 0 | GW16: =GW15*FI16/100 -> 0 | GZ16: =GZ15*FI16/100 -> 0 | HC16: =HC15*FI16/100 -> 0
AS17: Среднее количество изделий в договоре | BF17: =(BF9/BF10) -> #DIV/0!
C21: Продажи | AS21: Рассчеты | BY21: Эффективность | CR21: Заработная плата | DL21: Нарушения регламента работы | FI21: Сопровождение клиентов
A22: Февраль 2022 | C22: Показатели | L22: Дата | M22: 44197 | N22: 44198 | O22: 44199 | P22: 44200 | Q22: 44201 | R22: 44202 | S22: 44203 | T22: 44204 | U22: 44205 | V22: 44206 | W22: 44207 | X22: 44208 | Y22: 44209 | Z22: 44210 | AA22: 44211 | AB22: 44212 | AC22: 44213 | AD22: 44214 | AE22: 44215 | AF22: 44216 | AG22: 44217 | AH22: 44218 | AI22: 44219 | AJ22: 44220 | AK22: 44221 | AL22: 44222 | AM22: 44223 | AN22: 44224 | AO22: 44225 | AP22: 44226 | AQ22: 44227 | AS22: Ключевые показатели | BF22: Факт | BI22: План | BL22: Вып 100% | BO22: Бонус | BR22: Вып в % | BU22: Днев ПЛ | BY22: Ключевые конверсии | CM22: Факт | CO22: Сред | CR22: Мотивация менеджера | DH22: Сумма | DL22: Дисциплинарные нарушения | DX22: Сумм | DZ22: 44317 | EA22: 44318 | EB22: 44319 | EC22: 44320 | ED22: 44321 | EE22: 44322 | EF22: 44323 | EG22: 44324 | EH22: 44325 | EI22: 44326 | EJ22: 44327 | EK22: 44328 | EL22: 44329 | EM22: 44330 | EN22: 44331 | EO22: 44332 | EP22: 44333 | EQ22: 44334 | ER22: 44335 | ES22: 44336 | ET22: 44337 | EU22: 44338 | EV22: 44339 | EW22: 44340 | EX22: 44341 | EY22: 44342 | EZ22: 44343 | FA22: 44344 | FB22: 44345 | FC22: 44346 | FD22: 44347 | FE22: Итого | FI22: Название проекта | FM22: Казань ДаВинчи | FP22: Саранск Калабрия | FS22: Махачкала Карго58 | FV22: Омск Лусонелла
AS23: Количество новых лидов | BF23: =SUM(M26:AQ26) -> 0 | BI23: 0 | BL23: 0 | BO23: 0 | BR23: 0 | BU23: =(BI23-BF23)/'График'!AK8 -> 0 | BY23: Из лида в одобренный тест | CM23: =BF25*100/BF23 -> #DIV/0! | CO23: =((BF25*100/BF23)+CM5)/2 -> #DIV/0! | CR23: Сумма штрафов | DH23: =FE32 -> 2500
AS24: Количество результативных звонков | BF24: =SUM(M27:AQ27) -> 0 | BI24: 60 | BL24: =IF(BF24<BI24,BF24,IF(BF24>=BI24,BI24)) -> 0 | BO24: =2500*BR24/100 -> 0 | BR24: =BL24*100/BI24 -> 0 | BU24: =(BI24-BF24)/'График'!AK8 -> 2.6086957 | BY24: Из лида в оплаченный тест | CM24: =BF26*100/BF23 -> #DIV/0! | CO24: =((BF25*100/BF23)+CM6)/2 -> #DIV/0! | CR24: Бонус за выполнение KPI | DH24: =sum(BO24:BQ27,BO29) -> 0 | FI24: Сумма | FM24: 20000 | FP24: 10000 | FS24: 32000 | FV24: 20000
AS25: Кол-во одобренных тестов | BF25: =SUM(M28:AQ28) -> 0 | BI25: 30 | BL25: =IF(BF25<BI25,BF25,IF(BF25>=BI25,BI25)) -> 0 | BO25: =2500*BR25/100 -> 0 | BR25: =BL25*100/BI25 -> 0 | BU25: =(BI25-BF25)/'График'!AK8 -> 1.3043478 | BY25: Из лида в заключенный договор | CM25: =BF27*100/BF23 -> #DIV/0! | CO25: =((BF27*100/BF23)+CM7)/2 -> #DIV/0! | CR25: Общий % выполнения KPI | DH25: =sum(BR24,BR25,BR26,BR27,BR29)/5 -> 0 | FI25: Количество | FM25: 1 | FP25: 2 | FS25: 3 | FV25: 4 | FY25: 5 | GB25: 6 | GE25: 7 | GH25: 8 | GK25: 9 | GN25: 10 | GQ25: 11 | GT25: 12 | GW25: 13 | GZ25: 14 | HC25: 15
C26: Кол-во новых лидов | AS26: Кол-во оплаченных тестов | BF26: =SUM(M29:AQ29) -> 0 | BI26: 20 | BL26: =IF(BF26<BI26,BF26,IF(BF26>=BI26,BI26)) -> 0 | BO26: =2500*BR26/100 -> 0 | BR26: =BL26*100/BI26 -> 0 | BU26: =(BI26-BF26)/'График'!AK8 -> 0.86956522 | BY26: Из результативного звонка в одобренный тест | CM26: =BF25*100/BF24 -> #DIV/0! | CO26: =((BF25*100/BF24)+CM8)/2 -> #DIV/0! | CR26: Премия за сопровождение проектов за второй месяц | DH26: =FI9 -> 7500 | DL26: Ведение CRM | DX26: 200 | DZ26: 1 | EE26: 1 | EJ26: 1 | EO26: 1 | FE26: =sum(DZ26:FD26)*DX26 -> 800 | FI26: 2 месяц | FL26: % | FM26: 10 | FP26: 10 | FS26: 10 | FV26: 10 | FY26: 10 | GB26: 10 | GE26: 10 | GH26: 10 | GK26: 10 | GN26: 10 | GQ26: 10 | GT26: 10 | GW26: 10 | GZ26: 10 | HC26: 10
C27: Кол-во результативных звонков | AS27: Кол-во заключенных договоров | BF27: =SUM(M30:AQ30) -> 0 | BI27: 5 | BL27: =IF(BF27<BI27,BF27,IF(BF27>=BI27,BI27)) -> 0 | BO27: =2500*BR27/100 -> 0 | BR27: =BL27*100/BI27 -> 0 | BU27: =(BI27-BF27)/'График'!AK8 -> 0.2173913 | BY27: Из звонка в проведенный тест | CM27: =BF26*100/BF24 -> #DIV/0! | CO27: =((BF26*100/BF24)+CM9)/2 -> #DIV/0! | CR27: Премия за сопровождение проектов за третий месяц | DL27: Соблюдение регламентов и скриптов | DX27: 200 | EB27: 1 | FE27: =sum(DZ27:FD27)*DX27 -> 200 | FI27: =SUM(FM27:HD27) -> 8200 | FM27: =(FM24*FM26)/100 -> 2000 | FP27: =(FP24*FP26)/100 -> 1000 | FS27: =(FS24*FS26)/100 -> 3200 | FV27: =(FV24*FV26)/100 -> 2000 | FY27: =(FY24*FY26)/100 -> 0 | GB27: =(GB24*GB26)/100 -> 0 | GE27: =(GE24*GE26)/100 -> 0 | GH27: =(GH24*GH26)/100 -> 0 | GK27: =(GK24*GK26)/100 -> 0 | GN27: =(GN24*GN26)/100 -> 0 | GQ27: =(GQ24*GQ26)/100 -> 0 | GT27: =(GT24*GT26)/100 -> 0 | GW27: =(GW24*GW26)/100 -> 0 | GZ27: =(GZ24*GZ26)/100 -> 0 | HC27: =(HC24*HC26)/100 -> 0
C28: Кол-во одобренных тестов | AS28: Кол-во позиций в договоре | BF28: =SUM(M31:AQ31) -> 0 | BI28: 0 | BL28: 0 | BO28: 0 | BR28: 0 | BU28: =(BI28-BF28)/'График'!AK8 -> 0 | BY28: Из звонка в заключенный договор | CM28: =BF27*100/BF24 -> #DIV/0! | CO28: =((BF27*100/BF24)+CM10)/2 -> #DIV/0! | CR28: Зарплата менеджера без учета командного плана | DH28: =if(DH25>84,BF29*15%+DH24,if(DH25<85,BF29*5%+DH24)) -> 0 | DL28: Вовремя/неверно сданная отчетность | DX28: 500 | DZ28: 1 | FE28: =sum(DZ28:FD28)*DX28 -> 500 | FI28: 3 месяц | FL28: % | FY28: 5 | GB28: 5 | GE28: 5 | GH28: 5 | GK28: 5 | GN28: 5 | GQ28: 5 | GT28: 5 | GW28: 5 | GZ28: 5 | HC28: 5
C29: Кол-во оплаченных тестов | AS29: Сумма продаж | BF29: =SUM(N32:AQ32) -> 0 | BI29: 60000 | BL29: =IF(BF29<BI29,BF29,IF(BF29>=BI29,BI29)) -> 0 | BO29: =5000*BR29/100 -> 0 | BR29: =BL29*100/BI29 -> 0 | BU29: =(BI29-BF29)/'График'!AK8 -> 2608.6957 | BY29: Из одобренного теста в проведенный тест | CM29: =BF26*100/BF25 -> #DIV/0! | CO29: =((BF26*100/BF25)+CM11)/2 -> #DIV/0! | CR29: Зарплата менеджера с учетом командного плана | DH29: =if(BF30>=BI30,DH28+BO30,if(BF30<BI30,DH28))-FE32 -> -2500 | DL29: Опоздание без ув. причины | DX29: 800 | FE29: =sum(DZ29:FD29)*DX29 -> 0 | FI29: =SUM(FM29:HD29) -> 0 | FM29: =(FM24*FM28)/100 -> 0 | FP29: =(FP24*FP28)/100 -> 0 | FS29: =(FS24*FS28)/100 -> 0 | FV29: =(FV24*FV28)/100 -> 0 | FY29: =(FY24*FY28)/100 -> 0 | GB29: =(GB24*GB28)/100 -> 0 | GE29: =(GE24*GE28)/100 -> 0 | GH29: =(GH24*GH28)/100 -> 0 | GK29: =(GK24*GK28)/100 -> 0 | GN29: =(GN24*GN28)/100 -> 0 | GQ29: =(GQ24*GQ28)/100 -> 0 | GT29: =(GT24*GT28)/100 -> 0 | GW29: =(GW24*GW28)/100 -> 0 | GZ29: =(GZ24*GZ28)/100 -> 0 | HC29: =(HC24*HC28)/100 -> 0
C30: Кол-во заключенных договоров | AS30: Командный план | BF30: =sum(BF29+'Александр'!BI28) -> 0 | BI30: 60000 | BO30: 10000 | BR30: =BF30*100/BI30 -> 0 | BU30: =(BI30-BF30)/'График'!AK8 -> 2608.6957 | BY30: Из одобренного теста в заключенный договор | CM30: =BF27*100/BF25 -> #DIV/0! | CO30: =((BF27*100/BF25)+CM12)/2 -> #DIV/0! | DF30: Итого | DH30: =sum(DH29+DH26+DH27) -> 5000 | DL30: Неявка на работу | DX30: 1500 | FE30: =sum(DZ30:FD30)*DX30 -> 0 | FI30: Платные тесты
C31: Кол-во позиций в договоре | AS31: Остаток до выполнения личного плана | BF31: =BI29-BF29 -> 60000 | BY31: Из теста в заключенный договор | CM31: =BF27*100/BF26 -> #DIV/0! | CO31: =((BF27*100/BF26)+CM13)/2 -> #DIV/0! | DL31: Неверно составленное ТЗ | DX31: 1000 | EL31: 1 | FE31: =sum(DZ31:FD31)*DX31 -> 1000 | FI31: Название проекта | FM31: Омск Лусонелла | FP31: Иркутск Мебель | FS31: Краснодар РВСДизайн | FV31: Красноярс СибМебСерв | FY31: СПБ АрхитектураМеб | GB31: Уфа ЖивыеКухни | GE31: Челябинск Форест174 | GH31: Сургут АртВип | GK31: Самара МебельОтМастера | GN31: Курган НашаМебель | GQ31: Название Проекта | GT31: Название Проекта | GW31: Название Проекта | GZ31: Название Проекта | HC31: Название Проекта
C32: Сумма продаж | AS32: Средний чек | BF32: =BF29/BF27 -> #DIV/0! | FC32: Итого | FE32: =sum(FE26:FE31) -> 2500
AS33: Общее количество звонков | FI33: Сумма | FM33: 2000 | FP33: 1000 | FS33: 2000 | FV33: 2000 | FY33: 5000 | GB33: 2000 | GE33: 2000 | GH33: 2000 | GK33: 1000 | GN33: 1000
AS34: Общее количество минут разговора | FI34: 20 | FL34: % | FM34: =FM33*FI34/100 -> 400 | FP34: =FP33*FI34/100 -> 200 | FS34: =FS33*FI34/100 -> 400 | FV34: =FV33*FI34/100 -> 400 | FY34: =FY33*FI34/100 -> 1000 | GB34: =GB33*FI34/100 -> 400 | GE34: =GE33*FI34/100 -> 400 | GH34: =GH33*FI34/100 -> 400 | GK34: =GK33*FI34/100 -> 200 | GN34: =GN33*FI34/100 -> 200 | GQ34: =GQ33*FI34/100 -> 0 | GT34: =GT33*FI34/100 -> 0 | GW34: =GW33*FI34/100 -> 0 | GZ34: =GZ33*FI34/100 -> 0 | HC34: =HC33*FI34/100 -> 0
AS35: Среднее количество изделий в договоре | BF35: =(BF27/BF28) -> #DIV/0!
C39: Продажи | AS39: Рассчеты | BY39: Эффективность | CR39: Заработная плата | DL39: Нарушения регламента работы | FI39: Сопровождение клиентов
